Workbook

Sheet Caratula
B1: CONDOMINIO
B2: SANTA MARIA
B4: INFORME ECONOMICO
B5: Correspondiente al mes de Julio/2022
B8: INGRESOS
B10: Saldo del mes anterior | F10: 43209.36
B11: Saldo en efectivo | F11: 6.97
B12: Expensas julio | F12: =SUM(Ingresos!G44) -> 31450
B13: Otros | F13: =SUM(Ingresos!H44) -> 100
C15: Total ingresos | F15: =SUM(F10:F14) -> 74766.33
B18: EGRESOS
B19: Administracion | F19: =SUM(Egresos!D8) -> 3000
B20: Limpieza | F20: =SUM(Egresos!D9) -> 2400
B21: Mantenimiento de piscina y jardineria | F21: =SUM(Egresos!D10) -> 800
B22: Empresa de Seguridad Centinelas | F22: =SUM(Egresos!D11) -> 7400
B23: INTERLOGI mantenimiento de elevadores | F23: =SUM(Egresos!D12) -> 1252.81
B25: SAGUAPAC junio/22 | F25: =SUM(Egresos!D13) -> 5294.5
B26: CRE junio/22 | F26: =SUM(Egresos!D14) -> 1558.2
B28: Gastos varios | F28: =SUM(Egresos!E15) -> 7674
B29: Caja chica | F29: =SUM(Egresos!E27) -> 2181.6
C31: Total egresos | F31: =SUM(F19:F29) -> 31561.11
D34: Saldo al 30 de Julio | F34: =SUM(F15)-F31 -> 43205.22
C37: Saldo en efectivo | F37: =SUM(F34)-F38 -> 70.49
C38: Saldo en Banco | F38: 43134.73
C40: Saldo cierre | F40: =SUM(F37:F39) -> 43205.22

Sheet Ingresos
A1: Condominio SANTA MARIA
A2: Informe de Ingresos correspondiente a Julio/2022
A4: Nº | B4: Fecha | C4: Viviente | D4: Depto | E4: Recibo Nº | F4: Detalle de pago | G4: Exp Bs. | H4: Otros
A5: 1 | B5: 44744 | C5: Encarnación Yamal | D5: 703 | E5: 2376 | F5: Expensas de Junio/22 | G5: 650
A6: 2 | B6: 44744 | C6: Carol Gainsborg | D6: 804 | E6: 2377 | F6: Expensas de Junio/22 | G6: 650
A7: 3 | B7: 44744 | C7: Roxana de Payo | D7: 702 | E7: 2378 | F7: Expensas de Julio/22 | G7: 650
A8: 4 | B8: 44744 | C8: Oscar Diego Leaño | D8: 402 | E8: 2379 | F8: Expensas de Junio/22 | G8: 650
A9: 5 | B9: 44744 | C9: Ana Gloria Ponce de Leon | D9: 303 | E9: 2380 | F9: Expensas de febrero y marzo/22 | G9: 1400
A10: 6 | B10: 44746 | C10: Ignacio Vallido | D10: 602 | E10: 2381 | F10: Expensas de Julio/22 | G10: 500
A11: 7 | B11: 44746 | C11: Yenni Perrogon | D11: 204 | E11: 2382 | F11: Expensas de Julio/22 | G11: 650
A12: 8 | B12: 44746 | C12: Yenni Perrogon | D12: 603 | E12: 2383 | F12: Expensas de Julio/22 | G12: 650
A13: 9 | B13: 44746 | C13: Oscar Betancourt | D13: 902 | E13: 2384 | F13: Expensas de Junio y Julio/22 | G13: 1000
A14: 10 | B14: 44747 | C14: Carmen Sonia Añez | D14: 903 | E14: 2385 | F14: Expensas de Mayo/22 | G14: 650
A15: 11 | B15: 44747 | C15: Daniela Hurtado | D15: 1001 | E15: 2386 | F15: Expensas de Junio/22 | G15: 650
A16: 12 | B16: 44747 | C16: Gabriela Lazzo | D16: 901 | E16: 2387 | F16: Expensas de Julio/22 | G16: 650
... A36: 32 | B36: 44761 | C36: Oriana Hoyos | D36: 904 | E36: 2407 | F36: Expensas de Julio/22 | G36: 650
A37: 33 | C37: Anulado | E37: 2408
A38: 34 | B38: 44761 | C38: Viviana Roca | D38: 701 | E38: 2409 | F38: Expensas de abril, mayo, junio/22 | G38: 2100
A39: 35 | B39: 44765 | C39: Veronica Rau Bora | D39: 404 | E39: 2410 | F39: Alquiler del Area Social | H39: 100
A40: 36 | B40: 44771 | C40: Cecilia Escribano | D40: 704 | E40: 2411 | F40: Expensas de junio/22 (faltan 50) | G40: 650
A41: 37 | B41: 44771 | C41: Cecilia Escribano | D41: 704 | E41: 2412 | F41: Expensas de julio/22 y 50 de junio/22 | G41: 700
A42: 38 | B42: 44773 | C42: Oscar Diego Leaño | D42: 402 | E42: 2413 | F42: Expensas de Julio/22 | G42: 650
A43: 39 | B43: 44773 | C43: Gabriela Lazzo | D43: 901 | E43: 2414 | F43: Expensas de Agosto/22 | G43: 650
F44: Total Bs. | G44: =SUM(G5:G43) -> 31450 | H44: =SUM(H5:H43) -> 100
G45: =SUM(G44:H44) -> 31550

Sheet Egresos
A1: Condominio SANTA MARIA
A3: Informe de Egresos correspondiente a Julio/2022
A4: (Expresado en Bolivianos)
A6: Gastos Fijos | B6: N° Recibo | C6: Detalle | D6: Importe Pagado
D7: Parcial | E7: Total
A8: Pago de Servicios | B8: 14 | C8: Administración junio/2022 | D8: 3000 | E8: =SUM(D8:D12) -> 14852.81
B9: 12 | C9: Limpieza Alejandra Rodriguez junio/2022 | D9: 2400
B10: 13 | C10: Mantenimiento de piscina y jardineria junio/2022 | D10: 800
B11: 88 | C11: Empresa de Seguridad Centinelas junio/2022 | D11: 7400
B12: 24 | C12: INTERLOGY mantenimiento de elevadores junio/2022 | D12: 1252.81
B13: 682875 | C13: SAGUAPAC junio/2022 | D13: 5294.5 | E13: =SUM(D13:D14) -> 6852.7
B14: 127813 | C14: CRE junio/2022 | D14: 1558.2
A15: Gastos Varios | B15: 69088 | C15: Compra de material para los mesones de la churrasquera y trasnporte del matrial al condominio | D15: 652 | E15: =SUM(D15:D25) -> 7674
B16: 26 | C16: Alcides mano de obra 2 mesones para la churrasquera | D16: 800
B17: 2821 - 17 | C17: Compra de madera para el vaciado de los mesones de la churrasquera y transporte de la madera al condominio | D17: 242
B18: 18 | C18: Compra de dos conos de seguridad vial de silicona de 90cm y transporte | D18: 350
B19: 2770 - 19 | C19: Compra de dos reflectores para la terraza | D19: 160
B20: 25 | C20: Instalación de dos pantallas, calbleado nuevo, reflectrores terraza mano de obra | D20: 100
B21: 961318 | C21: Instalación de dos aleros para los parqueos que son afectados por las palomas | D21: 2600
B22: 28 | C22: Instalación de 10pantallas led en la terraza | D22: 150
B23: 29 | C23: 1er pago por puesta de ceramica en los mesones de la churrasquera | D23: 400
B24: 30 | C24: 2do pago por puesta de ceramica en los mesones de la churrasquera | D24: 300
B25: 2890 | C25: Compra de 8 sillas altas para la churrasquera | D25: 1920
A26: Caja Chica | C26: Caja chica | D26: 2200
B27: 30483 | C27: Compra de material de limpieza | D27: 321.8 | E27: =SUM(D27:D37) -> 2181.6
B28: 20 | C28: Transporte por compas de material de limpieza y material de construcción y banco | D28: 30
B29: 15 | C29: Esmerilado y señaleticas para el blindex de la entrada de la terrrqaza | D29: 359
B30: 2771 - 21 | C30: Compra de dos paneles led | D30: 60
B31: 22 | C31: Transporte por dejar las tapas para los niños con cancer | D31: 20
B32: 23 | C32: Compra de material para el calbleado nuevo de reflectrores terraza y transporte | D32: 155
B33: 24 | C33: Compra de 22 ladrillos de adobito, bolsas de yute y transporte | D33: 37
B34: 2844 - 27 | C34: Compra de 10 paneles led para la terraza, cotización de sillas y ceramica | D34: 342
B35: 316 - 37094 | C35: Compra de ceramia para los mesones de la churrasquera y transporte | D35: 586.8
B36: 5139 - 5737 - 6101- 6487 | C36: Agua para porteria | D36: 64
B37: 43183 | C37: Compras para la inauguración y Reunión Inormativa II | D37: 206
C38: Total gastos caja chica | D38: =SUM(D27:D37) -> 2181.6
C39: Saldo caja chica efectivo | D39: =SUM(D26)-D38 -> 18.4
C40: TOTAL Bs. | E40: =SUM(E8:E39) -> 31561.11

Sheet Estado de las expensas
A1: Estado Económico Julio/22
A2: # | B2: DEPTO | C2: PROPIETARIO | D2: ENE | E2: FEB | F2: MAR | G2: ABR | H2: MAY | I2: JUN | J2: JUL | K2: AGO | L2: SEP | M2: OCT | N2: NOV | O2: DIC | P2: TOTAL | Q2: TOTAL
A3: 1 | B3: 101 | C3: Elda Añez | D3: x | E3: 700 | F3: 700 | G3: 700 | H3: 700 | I3: 700 | J3: 650 | P3: =SUM(D3:O3) -> 4150 | Q3: =SUM(P3) -> 4150
A4: 2 | B4: 102 | C4: Ruddy Paz | D4: x | E4: x | F4: x | G4: x | H4: x | I4: x | J4: 650 | P4: =SUM(D4:O4) -> 650 | Q4: =SUM(P4) -> 650
A5: 3 | B5: 103 | C5: Jose Vilagut | D5: x | E5: x | F5: x | G5: x | H5: x | I5: x | J5: x | P5: =SUM(D5:O5) -> 0 | Q5: =SUM(P5) -> 0
A6: 4 | B6: 104 | C6: Denhiz Soliz | D6: x | E6: x | F6: x | G6: x | H6: x | I6: x | J6: 650 | P6: =SUM(D6:O6) -> 650 | Q6: =SUM(P6) -> 650
A7: 5 | B7: 201 | C7: Vania Llanos | D7: x | E7: x | F7: x | G7: x | H7: 700 | I7: 700 | J7: 650 | P7: =SUM(D7:O7) -> 2050 | Q7: =SUM(P7) -> 2050
A8: 6 | B8: 202 | C8: Zulma Santander | D8: x | E8: x | F8: x | G8: x | H8: x | I8: x | J8: x | P8: =SUM(D8:O8) -> 0 | Q8: =SUM(P8) -> 0
A9: 7 | B9: 203 | C9: Rosa Cordero | D9: x | E9: x | F9: x | G9: x | H9: x | I9: x | J9: x | P9: =SUM(D9:O9) -> 0 | Q9: =SUM(P9) -> 0
A10: 8 | B10: 204 | C10: Yenny Perrogon | D10: x | E10: x | F10: x | G10: x | H10: x | I10: x | J10: x | P10: =SUM(D10:O10) -> 0 | Q10: =SUM(P10) -> 0
A11: 9 | B11: 301 | C11: Glora Vera Viaña | D11: x | E11: x | F11: x | G11: x | H11: x | I11: 500 | J11: 500 | P11: =SUM(D11:O11) -> 1000 | Q11: =SUM(P11) -> 1000
A12: 10 | B12: 302 | C12: Urzula Echazu | D12: x | E12: x | F12: x | G12: x | H12: 700 | I12: 700 | J12: 650 | P12: =SUM(D12:O12) -> 2050 | Q12: =SUM(P12) -> 2050
A13: 11 | B13: 303 | C13: Ana Gloria Ponce de Leon | D13: x | E13: x | F13: x | G13: 700 | H13: 700 | I13: 700 | J13: 650 | P13: =SUM(D13:O13) -> 2750 | Q13: =SUM(P13) -> 2750
A14: 12 | B14: 304 | C14: Jorge Siles | D14: x | E14: x | F14: x | G14: x | H14: x | I14: x | J14: 650 | P14: =SUM(D14:O14) -> 650 | Q14: =SUM(P14) -> 650
A15: 13 | B15: 401 | C15: Silvana Justianano | D15: x | E15: x | F15: x | G15: x | H15: x | I15: x | J15: 500 | P15: =SUM(D15:O15) -> 500 | Q15: =SUM(P15) -> 500
A16: 14 | B16: 402 | C16: Oscar Diego Leaños | D16: x | E16: x | F16: x | G16: x | H16: x | I16: x | J16: x | P16: =SUM(D16:O16) -> 0 | Q16: =SUM(P16) -> 0
A17: 15 | B17: 403 | C17: Maria Norah Zubieta | D17: x | E17: x | F17: x | G17: x | H17: x | I17: x | J17: 650 | P17: =SUM(D17:O17) -> 650 | Q17: =SUM(P17) -> 650
A18: 16 | B18: 404 | C18: Miguel Rivas/Veronica Rau | D18: x | E18: x | F18: x | G18: x | H18: x | I18: 200 | J18: 650 | P18: =SUM(D18:O18) -> 850 | Q18: =SUM(P18) -> 850
A19: 17 | B19: 501 | C19: Romana Barbery de Moreno | D19: x | E19: x | F19: x | G19: x | H19: x | I19: 500 | J19: 500 | P19: =SUM(D19:O19) -> 1000 | Q19: =SUM(P19) -> 1000
A20: 18 | B20: 502 | C20: Andres Aguilera | D20: x | E20: x | F20: x | G20: x | H20: x | I20: x | J20: 650 | P20: =SUM(D20:O20) -> 650 | Q20: =SUM(P20) -> 650
A21: 19 | B21: 503 | C21: Edith Loma | D21: x | E21: x | F21: x | G21: x | H21: x | I21: x | J21: x | P21: =SUM(D21:O21) -> 0 | Q21: =SUM(P21) -> 0
A22: 20 | B22: 504 | C22: Sandra Bruno | D22: x | E22: x | F22: x | G22: x | H22: x | I22: x | J22: x | P22: =SUM(D22:O22) -> 0 | Q22: =SUM(P22) -> 0
A23: 21 | B23: 601 | C23: Romana Beatriz Moreno | D23: x | E23: x | F23: x | G23: x | H23: x | I23: 700 | J23: 650 | P23: =SUM(D23:O23) -> 1350 | Q23: =SUM(P23) -> 1350
A24: 22 | B24: 602 | C24: Monica Sahonero | D24: x | E24: x | F24: x | G24: x | H24: x | I24: x | J24: x | P24: =SUM(D24:O24) -> 0 | Q24: =SUM(P24) -> 0
A25: 23 | B25: 603 | C25: Yenny Perrogon | D25: x | E25: x | F25: x | G25: x | H25: x | I25: x | J25: x | P25: =SUM(D25:O25) -> 0 | Q25: =SUM(P25) -> 0
A26: 24 | B26: 604 | C26: Edgar Romero | D26: x | E26: x | F26: x | G26: x | H26: x | I26: 500 | J26: 500 | P26: =SUM(D26:O26) -> 1000 | Q26: =SUM(P26) -> 1000
A27: 25 | B27: 701 | C27: Viviana Roca | D27: x | E27: x | F27: x | G27: x | H27: x | I27: x | J27: 650 | P27: =SUM(D27:O27) -> 650 | Q27: =SUM(P27) -> 650
A28: 26 | B28: 702 | C28: Roxana de Payo- Fernando Payo | D28: x | E28: x | F28: x | G28: x | H28: x | I28: x | J28: x | P28: =SUM(D28:O28) -> 0 | Q28: =SUM(P28) -> 0
A29: 27 | B29: 703 | C29: Encarnacion Yamal | D29: x | E29: x | F29: x | G29: x | H29: x | I29: x | J29: 650 | P29: =SUM(D29:O29) -> 650 | Q29: =SUM(P29) -> 650
A30: 28 | B30: 704 | C30: Arturo Payo/Cecilia Escribano | D30: x | E30: x | F30: x | G30: x | H30: x | I30: x | J30: x | P30: =SUM(D30:O30) -> 0 | Q30: =SUM(P30) -> 0
A31: 29 | B31: 801 | C31: Magali Sandi Encinas | D31: x | E31: x | F31: x | G31: x | H31: x | I31: x | J31: 650 | P31: =SUM(D31:O31) -> 650 | Q31: =SUM(P31) -> 650
A32: 30 | B32: 802 | C32: Maria Elena Mendez | D32: x | E32: x | F32: x | G32: x | H32: x | I32: x | J32: x | P32: =SUM(D32:O32) -> 0 | Q32: =SUM(P32) -> 0
A33: 31 | B33: 803 | C33: Eliani Añez de Suarez | D33: x | E33: x | F33: x | G33: x | H33: x | I33: x | J33: x | P33: =SUM(D33:O33) -> 0 | Q33: =SUM(P33) -> 0
A34: 32 | B34: 804 | C34: Carol Gainsborg | D34: x | E34: x | F34: x | G34: x | H34: x | I34: x | J34: 650 | P34: =SUM(D34:O34) -> 650 | Q34: =SUM(P34) -> 650
A35: 33 | B35: 901 | C35: Gabiela Lazo | D35: x | E35: x | F35: x | G35: x | H35: x | I35: x | J35: x | P35: =SUM(D35:O35) -> 0 | Q35: =SUM(P35) -> 0
A36: 34 | B36: 902 | C36: Oscar Betancourt | D36: x | E36: x | F36: x | G36: x | H36: x | I36: x | J36: x | P36: =SUM(D36:O36) -> 0 | Q36: =SUM(P36) -> 0
A37: 35 | B37: 903 | C37: Carmen Sonia Añez | D37: x | E37: x | F37: x | G37: x | H37: 50 | I37: 700 | J37: 650 | P37: =SUM(D37:O37) -> 1400 | Q37: =SUM(P37) -> 1400
A38: 36 | B38: 904 | C38: Percy Christian Vega | D38: x | E38: x | F38: x | G38: x | H38: x | I38: x | J38: x | P38: =SUM(D38:O38) -> 0 | Q38: =SUM(P38) -> 0
A39: 37 | B39: 1001 | C39: Daniela Hurtado/Christian Sanjinez | D39: x | E39: x | F39: x | G39: x | H39: x | I39: x | J39: 650 | P39: =SUM(D39:O39) -> 650 | Q39: =SUM(P39) -> 650
A40: 38 | B40: 1002 | C40: Zunner Valverde | D40: 20000 | E40: 500 | F40: 500 | G40: 500 | H40: 500 | I40: 500 | J40: 500 | P40: =SUM(D40:O40) -> 23000 | Q40: =SUM(P40) -> 23000
...
