Workbook

Sheet Caratula
B1: CONDOMINIO
B2: SANTA MARIA
B4: INFORME ECONOMICO
B5: Correspondiente al mes de Febrero/2024
B7: INGRESOS
B9: Saldo del mes anterior | F9: 39124.93
B10: Saldo en efectivo | F10: -1.8
B11: Expensas febrero | F11: =SUM(Ingresos!G46) -> 38850
B12: Cuota Extraodinaria | F12: =SUM(Ingresos!H46) -> 9398
B13: Otros | F13: =SUM(Ingresos!I46) -> 100
C15: Total ingresos | F15: =SUM(F9:F14) -> 87471.13
B17: EGRESOS
B18: Administracion | F18: =SUM(Egresos!E11) -> 3090
B19: Limpieza | F19: =SUM(Egresos!E13) -> 2400
B20: Mantenimiento de piscina | F20: =SUM(Egresos!E19) -> 600
B21: Servicio de Porteria Santos Cardenas | F21: =SUM(Egresos!E16) -> 6600
B22: INTERLOGI mantenimiento de elevadores | F22: =SUM(Egresos!E20) -> 1252.8
B24: SAGUAPAC febrero/24 | F24: =SUM(Egresos!E8) -> 4890.9
B25: CRE febrero/24 | F25: =SUM(Egresos!E9) -> 1508.6
B26: Internet enero/24 | F26: =SUM(Egresos!E10) -> 143
B28: Gastos Varios
B29: Administración | F29: =SUM(Egresos!E12) -> 30
B30: Limpieza | F30: =SUM(Egresos!E14:E15) -> 345.9
B31: Portería | F31: =SUM(Egresos!E17:E18) -> 75
B32: Piscina | F32: 0
B33: Elevadores | F33: =SUM(Egresos!E21) -> 700
B34: Mantenimiento del edificio | F34: =SUM(Egresos!F22) -> 1672.39
B35: Mantenimiento de jardineria | F35: =SUM(Egresos!E36:E38) -> 20
C36: Total egresos | F36: =SUM(F18:F35) -> 23328.59
D38: Saldo al 29 de febrero/23 | F38: =SUM(F15)-F36 -> 64142.54
C40: Saldo en efectivo | F40: =SUM(F38)-F41 -> 154.91
C41: Saldo en Banco | F41: 63987.63
C43: Saldo cierre | F43: =SUM(F40:F41) -> 64142.54
C45: Cuota Extraordinaria | F45: =SUM(F12)+23444 -> 32842
C46: Saldo disponible | F46: =SUM(F43)-F45 -> 31300.54

Sheet Ingresos
A1: Condominio SANTA MARIA
A2: Informe de Ingresos correspondiente a febrero/24
A4: Nº | B4: Fecha | C4: Viviente | D4: Depto | E4: Recibo Nº | F4: Detalle de pago | G4: Exp Bs. | H4: Cuota Extraordinaria | I4: Otros
A5: 1 | B5: 45323 | C5: Cecilia Escribano | D5: 704 | E5: 448 | F5: Expensas de enero/24 | G5: 650
A6: 2 | B6: 45324 | C6: Cristhian Vega | D6: 904 | E6: 449 | F6: Expensas de enero/24; Quinta cuota extraordinaria | G6: 650 | H6: 350
A7: 3 | B7: 45324 | C7: Yenny Perrogon | D7: 204 | E7: 450 | F7: Expensas de febrero/24 | G7: 650
A8: 4 | B8: 45324 | C8: Yenny Perrogon | D8: 603 | E8: 451 | F8: Expensas de febrero/24 | G8: 650
A9: 5 | B9: 45325 | C9: Rosa Carrero | D9: 203 | E9: 452 | F9: Quinta cuota extraordinaria | H9: 348
A10: 6 | B10: 45327 | C10: Edith Loma | D10: 503 | E10: 453 | F10: Expensas de febrero/24; cuarta cuota extraordinaria | G10: 500 | H10: 350
A11: 7 | B11: 45327 | C11: Ariel Ortega | D11: 203 | E11: 454 | F11: Expensas de enero/24 | G11: 650
A12: 8 | B12: 45327 | C12: Edgar Romero | D12: 604 | E12: 455 | F12: Expensas de enero/24 | G12: 650
A13: 9 | B13: 45327 | C13: Daniela Hurtado | D13: 1001 | E13: 456 | F13: Expensas de enero/24 | G13: 650
A14: 10 | B14: 45327 | C14: Milka Barrientos | D14: 401 | E14: 457 | F14: Expensas de enero/24 | G14: 650
A15: 11 | B15: 45327 | C15: Roxana Añez de Payo | D15: 702 | E15: 458 | F15: Expensas de febrero/24 | G15: 650
A16: 12 | B16: 45327 | C16: Roxana Añez de Payo | D16: 702 | E16: 459 | F16: Quinta cuota extraordinaria | H16: 350
A17: 13 | B17: 45327 | C17: Maria Norah Zubieta | D17: 403 | E17: 460 | F17: Expensas de enero/24; Quinta cuota extraordinaria | G17: 650 | H17: 350
A18: 14 | B18: 45328 | C18: Lorena Landivar | D18: 1004 | E18: 461 | F18: Expensas de enero/24 | G18: 700
A19: 15 | B19: 45328 | C19: Victor Hugo Inchausty | D19: 602 | E19: 462 | F19: Expensas de marzo/24; quinta cuota extraordinaria | G19: 650 | H19: 350
A20: 16 | B20: 45328 | C20: Andres Aguilera | D20: 502 | E20: 463 | F20: Expensas de enero/24, a cuenta de febrero 150 bs; quinta cuota extra | G20: 650 | H20: 350
A21: 17 | B21: 45328 | C21: Miguel Duran | D21: 101 | E21: 464 | F21: Expensas de enero/24 | G21: 650
A22: 18 | B22: 45329 | C22: Jorge Armando Siles | D22: 304 | E22: 465 | F22: Alquiler de la terraza | I22: 100
A23: 19 | B23: 45329 | C23: Carmen Sonia Añez | D23: 903 | E23: 466 | F23: Expensas de enero/24 | G23: 700
A24: 20 | B24: 45330 | C24: Carolina Bejar | D24: 301 | E24: 467 | F24: Expensa de febrero/24, a cuenta de marzo 150 bs; sexta cuota extraor | G24: 650 | H24: 350
A25: 21 | B25: 45332 | C25: Julia Colomo | D25: 104 | E25: 468 | F25: Expensas de enero/24 | G25: 650
A26: 33 | B26: 45332 | C26: Carmen Sonia Añez | D26: 903 | E26: 469 | F26: Primer pago de la cuota extraordinaria | H26: 1000
A27: 34 | B27: 45332 | C27: Urzula Echazú | D27: 302 | E27: 470 | F27: Expensas de enero/24 | G27: 700
A28: 35 | B28: 45332 | C28: Urzula Echazú | D28: 302 | E28: 471 | F28: 3ra Cuota extraordinaria | H28: 350
A29: 36 | B29: 45333 | C29: Jorge Siles | D29: 301 | E29: 472 | F29: Expensas de enero/24 | G29: 500
A30: 37 | B30: 45333 | C30: Jimena Villarraga | D30: 802 | E30: 473 | F30: Expensas de febrero/24 | G30: 650
A31: 38 | B31: 45336 | C31: Wendy Davila | D31: 703 | E31: 474 | F31: Expensas de octubre/23; 2da cuota extraordinaria | G31: 650 | H31: 350
A32: 39 | B32: 45336 | C32: Yenny Perrogon | D32: 204/603 | E32: 475 | F32: 2da cuota extraoridinaria departamentos 204 y 603 | H32: 700
A33: 40 | B33: 45338 | C33: Paola Gomez | D33: 801 | E33: 476 | F33: Expensas de enero/24 | G33: 700
A34: 41 | B34: 45341 | C34: Eliani Añez de Suarez | D34: 803 | E34: 477 | F34: Expensas de noviembre y diciembre/23; Enero y febrero/24 segunda cuota extraordinaria | G34: 2750 | H34: 350
A35: 42 | B35: 45341 | C35: Oscar Betancourt | D35: 902 | E35: 478 | F35: Expensas de diciembre/23, enero y febrero/24; 3 cuotas extraordinarias | G35: 1500 | H35: 1050
A36: 43 | B36: 45343 | C36: Viviana Miranda | D36: 504 | E36: 479 | F36: Expensas gestion 2024 y gestión 2025 (cancelado hasta diciembre 2025) | G36: 15650
A37: 44 | B37: 45348 | C37: Juan Pablo Alvarado | D37: 103 | E37: 480 | F37: 5ta Cuota extraordinaria | H37: 350
A38: 45 | B38: 45348 | C38: Juan Pablo Alvarado | D38: 103 | E38: 481 | F38: Expensas de febrero/24 | G38: 650
A39: 46 | B39: 45350 | C39: Romy Moreno | D39: 601 | E39: 482 | F39: Expensas de diciembre/23y enero24 | G39: 1400
A40: 47 | B40: 45350 | C40: Romy Moreno | D40: 601 | E40: 483 | F40: 3ra, 4ta y 5ta cuota extraordinaria | H40: 1050
A41: 48 | B41: 45350 | C41: Romana Barbery | D41: 501 | E41: 484 | F41: Expensas de diciembre/23y enero24 | G41: 1400
...

Sheet Egresos
A1: Condominio SANTA MARIA
A3: Informe de egresos correspondiente a febrero/2024
A4: (Expresado en Bolivianos)
A6: Egresos | B6: N° Recibo | C6: Fecha | D6: Detalle | E6: Importe Pagado
E7: Parcial | F7: Total
A8: Pago de Servicios Básicos | B8: 6157267 | C8: 45345 | D8: SAGUAPAC febrero/24 | E8: 4890.9 | F8: =SUM(E8:E10) -> 6542.5
B9: 914654 | C9: 45345 | D9: CRE febrero/24 | E9: 1508.6
B10: 7129462 | C10: 45345 | D10: Internet Entel enero/24 | E10: 143
A11: Gastos Administración | B11: 278 | C11: 45324 | D11: Administración enero/24 | E11: 3090 | F11: =SUM(E11:E12) -> 3120
B12: 279 | C12: 45325 | D12: Entrega de las tapas para los niños con cancer oncologico, transporte | E12: 30
A13: Gastos Limpieza | B13: 8 | C13: 45324 | D13: Limpieza Cleaning Full enero/24 | E13: 2400 | F13: =SUM(E13:E15) -> 2745.9
B14: 79388 | C14: 45325 | D14: Compra del material de limpieza | E14: 335.9
B15: 281 | C15: 45327 | D15: Transportes por compra de material de limpieza | E15: 10
A16: Gastos porteria | B16: 9029551 | C16: 45324 | D16: Porteria CyP Multiservicios enero/24 | E16: 6600 | F16: =SUM(E16:E18) -> 6675
B17: 19761 - 20485 - 20754 - 21075 | D17: Compra de bidones de agua | E17: 64
B18: 238148158 | C18: 45341 | D18: Compra de tarjeta Entel de 10 Bs | E18: 11
A19: Mantenimiento piscina | B19: 6259 | C19: 45324 | D19: Mantenimiento de piscina AQUACENTER enero/24 | E19: 600 | F19: =SUM(E19) -> 600
A20: Gastos mantenimiento elevadodores | B20: 6414 | C20: 45327 | D20: INTERLOGI mantenimiento de elevadores enero/24 | E20: 1252.8 | F20: =SUM(E20:E21) -> 1952.8
B21: 375 | C21: 45345 | D21: IMECAG, mantenimiento y reparación de 2 modulos de control de pulsadores | E21: 700
A22: Gastos mantenimiento del edificio | B22: 280 | C22: 45327 | D22: Compra de veneno para fumigación del deposito y garajes hierba y transporte | E22: 120 | F22: =SUM(E22:E37) -> 1672.39
B23: 283 | C23: 45331 | D23: Compra de fumigadora de 12 lts | E23: 170
B24: 284 | C24: 45332 | D24: Arreglo filtración del lado de la piscina ,limpieza de desague de edificio, pago final del arreglo del departamento 1001 | E24: 150
B25: 285 | C25: 45342 | D25: Rrefacción de piso de la ceramica de la terraza la churrasquera 70 ceramicas sueltas | E25: 90
B26: 9088301 | C26: 45341 | D26: Compra de 3 bolsas de cemento cola arreglo piso de la terraza 150 ceramicas sueltas | E26: 123
B27: 286 | C27: 45342 | D27: Rrefacción de piso de la ceramica de la terraza la churrasquera 150 ceramicas sueltas | E27: 350
B28: 813 | C28: 45345 | D28: Flotador para el tanque de ingreso de agua | E28: 135
B29: 287 | C29: 45345 | D29: Alcides cambio de flotador mano de obra | E29: 50
B30: 288 | C30: 45348 | D30: Rrefacción de piso de la ceramica de la terraza lado buleras | E30: 100
B31: 204743 | C31: 45349 | D31: Cemento cola con impermeablizante Sika | E31: 61.66
B32: 38979 | C32: 45350 | D32: Disco de desgaste, esmeril para corte de ceramicas | E32: 70
B33: 204741 | C33: 45318 | D33: Compra de 2 focos para elevadores y una pala para jardineria | E33: 87.73
B34: 289 | C34: 45351 | D34: Transporte por compra de focos y cemento cola (27/02/24);transporte por compra de flotador (23/02/24); transporte por compra de cemento cola (28/02/24) | E34: 45
B35: 290 | C35: 45351 | D35: Refacción de piso de la ceramica de la terraza lado churrasquera, primer pago de 250 bs cotizados (se le debe 40 bs de la compra del; 150bs saldo pago refacción ) | E35: 100
A36: Gastos de mantenimiento de jardines | B36: 282 | C36: 45327 | D36: compra de pita para podar jardin, podadora electrica | E36: 20 | F36: =SUM(E36:E37) -> 20
D38: Total | F38: =SUM(F8:F37) -> 23328.59

Sheet Estado de las expensas
A1: Expensas Febrero/24
A2: # | B2: DEPTO | C2: PROPIETARIO | D2: G-2022 | E2: G-2023 | F2: ENE | G2: FEB | H2: MAR | I2: ABR | J2: MAY | K2: JUN | L2: JUL | M2: AGO | N2: SEP | O2: OCT | P2: NOV | Q2: DIC | R2: G-2024
A3: 1 | B3: 101 | C3: Elda Añez (con compromiso de pago) | D3: 1500 | E3: 4800 | F3: x | R3: =SUM(D3:Q3) -> 6300
A4: 2 | B4: 102 | C4: Ruddy Paz | D4: 0 | E4: 0 | F4: x | R4: =SUM(D4:Q4) -> 0
A5: 3 | B5: 103 | C5: Jose Vilaguth | D5: 0 | E5: 0 | F5: x | G5: x | R5: =SUM(D5:Q5) -> 0
A6: 4 | B6: 104 | C6: Denhiz Soliz | D6: 0 | E6: 0 | F6: x | G6: x | R6: =SUM(D6:Q6) -> 0
A7: 5 | B7: 201 | C7: Vania Llanos | D7: 0 | E7: 0 | F7: 700 | R7: =SUM(D7:Q7) -> 700
A8: 6 | B8: 202 | C8: Carolina Inturias | D8: 0 | E8: 0 | F8: x | G8: x | R8: =SUM(D8:Q8) -> 0
A9: 7 | B9: 203 | C9: Rosa Cordero | D9: 0 | E9: 0 | F9: x | R9: =SUM(D9:Q9) -> 0
A10: 8 | B10: 204 | C10: Yenny Perrogon | D10: 0 | E10: 0 | F10: x | G10: x | R10: =SUM(D10:Q10) -> 0
A11: 9 | B11: 301 | C11: Glora Vera Viaña | D11: 0 | E11: 0 | F11: x | G11: x | R11: =SUM(D11:Q11) -> 0
A12: 10 | B12: 302 | C12: Urzula Echazu | D12: 0 | E12: 0 | F12: x | R12: =SUM(D12:Q12) -> 0
A13: 11 | B13: 303 | C13: Ana Gloria Ponce de Leon | D13: 0 | E13: 8150 | F13: 800 | R13: =SUM(D13:Q13) -> 8950
A14: 12 | B14: 304 | C14: Jorge Siles | D14: 0 | E14: 0 | F14: x | R14: =SUM(D14:Q14) -> 0
A15: 13 | B15: 401 | C15: Milka Barrientos | D15: 0 | E15: 0 | F15: x | R15: =SUM(D15:Q15) -> 0
A16: 14 | B16: 402 | C16: Oscar Diego Leaños | D16: 0 | E16: 0 | F16: x | G16: x | H16: x | I16: x | R16: =SUM(D16:Q16) -> 0
A17: 15 | B17: 403 | C17: Maria Norah Zubieta | D17: 0 | E17: 0 | F17: x | R17: =SUM(D17:Q17) -> 0
A18: 16 | B18: 404 | C18: Miguel Rivas/Veronica Rau | D18: 0 | E18: 2250 | F18: 800 | R18: =SUM(D18:Q18) -> 3050
A19: 17 | B19: 501 | C19: Romana Barbery de Moreno | D19: 0 | E19: 0 | F19: x | R19: =SUM(D19:Q19) -> 0
A20: 18 | B20: 502 | C20: Andres Aguilera | D20: 0 | E20: 0 | F20: x | R20: =SUM(D20:Q20) -> 0
A21: 19 | B21: 503 | C21: Edith Loma | D21: 0 | E21: 0 | F21: x | G21: x | R21: =SUM(D21:Q21) -> 0
A22: 20 | B22: 504 | C22: Viviana Miranda | D22: 0 | E22: 0 | F22: x | G22: x | H22: x | I22: x | J22: x | K22: x | L22: x | M22: x | N22: x | O22: x | P22: x | Q22: x | R22: =SUM(D22:Q22) -> 0
A23: 21 | B23: 601 | C23: Romana Beatriz Moreno | D23: 0 | E23: 0 | F23: x | R23: =SUM(D23:Q23) -> 0
A24: 22 | B24: 602 | C24: Victor Hugo Inchauste | D24: 0 | E24: 0 | F24: x | G24: x | H24: x | R24: =SUM(D24:Q24) -> 0
A25: 23 | B25: 603 | C25: Yenny Perrogon | D25: 0 | E25: 0 | F25: x | G25: x | R25: =SUM(D25:Q25) -> 0
A26: 24 | B26: 604 | C26: Edgar Romero | D26: 0 | E26: 0 | F26: x | R26: =SUM(D26:Q26) -> 0
A27: 25 | B27: 701 | C27: Viviana Roca | D27: 0 | E27: 400 | F27: 700 | R27: =SUM(D27:Q27) -> 1100
A28: 26 | B28: 702 | C28: Roxana de Payo- Fernando Payo | D28: 0 | E28: 0 | F28: x | G28: x | R28: =SUM(D28:Q28) -> 0
A29: 27 | B29: 703 | C29: Encarnacion Yamal | D29: 0 | E29: 1200 | F29: 600 | R29: =SUM(D29:Q29) -> 1800
A30: 28 | B30: 704 | C30: Arturo Payo/Cecilia Escribano | D30: 0 | E30: 0 | F30: x | R30: =SUM(D30:Q30) -> 0
A31: 29 | B31: 801 | C31: Magali Sandi Encinas | D31: 0 | E31: 0 | F31: x | R31: =SUM(D31:Q31) -> 0
A32: 30 | B32: 802 | C32: Jimena Villarraga | D32: 0 | E32: 0 | F32: x | G32: x | R32: =SUM(D32:Q32) -> 0
A33: 31 | B33: 803 | C33: Eliani Añez de Suarez | D33: 0 | E33: 0 | F33: x | G33: x | R33: =SUM(D33:Q33) -> 0
A34: 32 | B34: 804 | C34: Carol Gainsborg | D34: 0 | E34: 0 | F34: x | R34: =SUM(D34:Q34) -> 0
A35: 33 | B35: 901 | C35: Gabiela Lazzo | D35: 0 | E35: 3200 | F35: 800 | R35: =SUM(D35:Q35) -> 4000
A36: 34 | B36: 902 | C36: Oscar Betancourt | D36: 0 | E36: 0 | F36: x | G36: x | R36: =SUM(D36:Q36) -> 0
A37: 35 | B37: 903 | C37: Carmen Sonia Añez | D37: 0 | E37: 0 | F37: x | R37: =SUM(D37:Q37) -> 0
A38: 36 | B38: 904 | C38: Cristhian Vega | D38: 0 | E38: 0 | F38: x | R38: =SUM(D38:Q38) -> 0
A39: 37 | B39: 1001 | C39: Daniela Hurtado/Christian Sanjinez | D39: 0 | E39: 0 | F39: x | R39: =SUM(D39:Q39) -> 0
A40: 38 | B40: 1002 | C40: Banco Mercantil Santa Cruz | D40: 30000 | E40: 7200 | F40: 600 | G40: 600 | R40: =SUM(D40:Q40) -> 38400
...

Sheet Cuotas extraordinarias
A1: Cuotas extraordinarias
A2: # | B2: DEPTO | C2: PROPIETARIO | D2: 1ra | E2: 2da | F2: 3ra | G2: 4ta | H2: 5ta | I2: 6ta | J2: 7ma | K2: 8va | L2: 9na | M2: 10ma | N2: 11va | O2: 12va | P2: TOTAL
A3: 1 | B3: 101 | C3: Elda Añez (con compromiso de pago) | P3: =SUM(D3:O3) -> 0
A4: 2 | B4: 102 | C4: Ruddy Paz | D4: 350 | E4: 350 | F4: 350 | G4: 350 | P4: =SUM(D4:O4) -> 1400
A5: 3 | B5: 103 | C5: Jose Vilaguth | D5: 350 | E5: 350 | F5: 350 | G5: 350 | H5: 350 | P5: =SUM(D5:O5) -> 1750
A6: 4 | B6: 104 | C6: Denhiz Soliz | P6: =SUM(D6:O6) -> 0
A7: 5 | B7: 201 | C7: Vania Llanos | D7: 350 | E7: 350 | F7: 350 | G7: 350 | P7: =SUM(D7:O7) -> 1400
A8: 6 | B8: 202 | C8: Carlina Inturias | D8: 350 | E8: 350 | F8: 350 | G8: 350 | H8: 350 | P8: =SUM(D8:O8) -> 1750
A9: 7 | B9: 203 | C9: Rosa Cordero | D9: 350 | E9: 350 | F9: 350 | G9: 350 | H9: 350 | P9: =SUM(D9:O9) -> 1750
A10: 8 | B10: 204 | C10: Yenny Perrogon | D10: 350 | E10: 350 | P10: =SUM(D10:O10) -> 700
A11: 9 | B11: 301 | C11: Glora Vera Viaña | D11: 350 | E11: 350 | F11: 350 | G11: 350 | H11: 350 | I11: 350 | P11: =SUM(D11:O11) -> 2100
A12: 10 | B12: 302 | C12: Urzula Echazu | D12: 350 | E12: 350 | F12: 350 | P12: =SUM(D12:O12) -> 1050
A13: 11 | B13: 303 | C13: Ana Gloria Ponce de Leon | D13: 350 | P13: =SUM(D13:O13) -> 350
A14: 12 | B14: 304 | C14: Jorge Siles | P14: =SUM(D14:O14) -> 0
A15: 13 | B15: 401 | C15: Milka Barrientos | P15: =SUM(D15:O15) -> 0
A16: 14 | B16: 402 | C16: Oscar Diego Leaños | P16: =SUM(D16:O16) -> 0
A17: 15 | B17: 403 | C17: Maria Norah Zubieta | D17: 350 | E17: 350 | F17: 350 | G17: 350 | H17: 350 | P17: =SUM(D17:O17) -> 1750
A18: 16 | B18: 404 | C18: Miguel Rivas/Veronica Rau | D18: Un solo pago al final | P18: =SUM(D18:O18) -> 0
A19: 17 | B19: 501 | C19: Romana Barbery de Moreno | D19: 350 | E19: 350 | F19: 350 | G19: 350 | H19: 350 | P19: =SUM(D19:O19) -> 1750
A20: 18 | B20: 502 | C20: Andres Aguilera | D20: 350 | E20: 350 | F20: 350 | G20: 350 | H20: 350 | P20: =SUM(D20:O20) -> 1750
A21: 19 | B21: 503 | C21: Edith Loma | D21: 350 | E21: 350 | F21: 350 | G21: 350 | P21: =SUM(D21:O21) -> 1400
A22: 20 | B22: 504 | C22: Viviana Miranda | D22: un solo pago | P22: =SUM(D22:O22) -> 0
A23: 21 | B23: 601 | C23: Romana Beatriz Moreno | D23: 350 | E23: 350 | F23: 350 | G23: 350 | H23: 350 | P23: =SUM(D23:O23) -> 1750
A24: 22 | B24: 602 | C24: Victor Hugo Inchausty | D24: 350 | E24: 350 | F24: 350 | G24: 350 | H24: 350 | P24: =SUM(D24:O24) -> 1750
A25: 23 | B25: 603 | C25: Yenny Perrogon | D25: 350 | E25: 350 | P25: =SUM(D25:O25) -> 700
A26: 24 | B26: 604 | C26: Edgar Romero | P26: =SUM(D26:O26) -> 0
A27: 25 | B27: 701 | C27: Viviana Roca | D27: Un solo pago al final | P27: =SUM(D27:O27) -> 0
A28: 26 | B28: 702 | C28: Roxana de Payo- Fernando Payo | D28: 350 | E28: 350 | F28: 350 | G28: 350 | H28: 350 | P28: =SUM(D28:O28) -> 1750
A29: 27 | B29: 703 | C29: Encarnacion Yamal | D29: 350 | E29: 350 | P29: =SUM(D29:O29) -> 700
A30: 28 | B30: 704 | C30: Arturo Payo/Cecilia Escribano | D30: Un solo pago al final | P30: =SUM(D30:O30) -> 0
A31: 29 | B31: 801 | C31: Magali Sandi Encinas | D31: Un solo pago al final | P31: =SUM(D31:O31) -> 0
A32: 30 | B32: 802 | C32: Jimena Villarraga | D32: Un solo pago al final | P32: =SUM(D32:O32) -> 0
A33: 31 | B33: 803 | C33: Eliani Añez de Suarez | D33: 350 | E33: 350 | P33: =SUM(D33:O33) -> 700
A34: 32 | B34: 804 | C34: Carol Gainsborg | D34: 350 | E34: 350 | F34: 350 | G34: 350 | P34: =SUM(D34:O34) -> 1400
A35: 33 | B35: 901 | C35: Gabiela Lazzo | D35: 350 | E35: 350 | P35: =SUM(D35:O35) -> 700
A36: 34 | B36: 902 | C36: Oscar Betancourt | D36: 350 | E36: 350 | F36: 350 | G36: 350 | H36: 350 | P36: =SUM(D36:O36) -> 1750
A37: 35 | B37: 903 | C37: Carmen Sonia Añez | D37: 350 | E37: 350 | F37: 300 | P37: =SUM(D37:O37) -> 1000
A38: 36 | B38: 904 | C38: Cristhian Vega | D38: 350 | E38: 350 | F38: 350 | G38: 350 | H38: 350 | P38: =SUM(D38:O38) -> 1750
A39: 37 | B39: 1001 | C39: Daniela Hurtado/Christian Sanjinez | P39: =SUM(D39:O39) -> 0
A40: 38 | B40: 1002 | C40: Banco Mercantil Santa Cruz | P40: =SUM(D40:O40) -> 0
...
